2020-09-15 12:22:48,138 - ImportJar.py [line:17] - INFO: 所需模块导入成功 Required modules imported successfully！
2020-09-15 12:22:48,317 - Adb_Tools.py [line:89] - INFO: 设备连接成功['2252d57a']
2020-09-15 12:22:48,317 - Adb_Tools.py [line:49] - INFO: 上级所在目录为：E:\WorkSpace\PycharmProjects\UiAutomationFramework
2020-09-15 12:22:48,317 - Adb_Tools.py [line:51] - INFO: APK存储路径：E:\WorkSpace\PycharmProjects\UiAutomationFramework\APKPath
2020-09-15 12:22:48,317 - Adb_Tools.py [line:166] - INFO: 成功接收到check_local_file方法return的安装包绝对路径：E:\WorkSpace\PycharmProjects\UiAutomationFramework\APKPath\qq_8.4.10.4675vdefault_CheckIn_537065629_debug.apk
2020-09-15 12:22:48,318 - Adb_Tools.py [line:167] - INFO: 检索到的设备：['2252d57a']
2020-09-15 12:22:48,318 - Adb_Tools.py [line:169] - INFO: 当前终端ID：2252d57a，安装过程中请勿移除USB连接！！！
2020-09-15 17:26:18,846 - ImportJar.py [line:17] - INFO: 所需模块导入成功 Required modules imported successfully！
2020-09-15 17:26:19,008 - Adb_Tools.py [line:89] - INFO: 设备连接成功['D8H6R19630008844']
2020-09-15 17:26:19,009 - Adb_Tools.py [line:49] - INFO: 上级所在目录为：E:\WorkSpace\PycharmProjects\UiAutomationFramework
2020-09-15 17:26:19,009 - Adb_Tools.py [line:51] - INFO: APK存储路径：E:\WorkSpace\PycharmProjects\UiAutomationFramework\APKPath
2020-09-15 17:26:19,009 - Adb_Tools.py [line:166] - INFO: 成功接收到check_local_file方法return的安装包绝对路径：E:\WorkSpace\PycharmProjects\UiAutomationFramework\APKPath\qq_8.4.10.4675vdefault_CheckIn_537065629_debug.apk
2020-09-15 17:26:19,009 - Adb_Tools.py [line:167] - INFO: 检索到的设备：['D8H6R19630008844']
2020-09-15 17:26:19,009 - Adb_Tools.py [line:169] - INFO: 当前终端ID：D8H6R19630008844，安装过程中请勿移除USB连接！！！
2020-09-15 17:26:27,996 - Adb_Tools.py [line:176] - ERROR: 设备：D8H6R19630008844安装失败adb: failed to install E:\WorkSpace\PycharmProjects\UiAutomationFramework\APKPath\qq_8.4.10.4675vdefault_CheckIn_537065629_debug.apk: Failure [INSTALL_FAILED_ABORTED: User rejected permissions]
2020-09-15 19:07:29,524 - remote_connection.py [line:117] - INFO: Could not connect to port 4723 on host 127.0.0.1
2020-09-15 19:07:29,524 - remote_connection.py [line:136] - INFO: Could not get IP address for host: 127.0.0.1
2020-09-15 19:07:31,529 - connectionpool.py [line:752] - WARNING: Retrying (Retry(total=2, connect=None, read=None, redirect=None, status=None)) after connection broken by 'NewConnectionError('<urllib3.connection.HTTPConnection object at 0x0000024E35B92A08>: Failed to establish a new connection: [WinError 10061] 由于目标计算机积极拒绝，无法连接。')': /wd/hub/session
2020-09-15 19:07:33,533 - connectionpool.py [line:752] - WARNING: Retrying (Retry(total=1, connect=None, read=None, redirect=None, status=None)) after connection broken by 'NewConnectionError('<urllib3.connection.HTTPConnection object at 0x0000024E35BA6408>: Failed to establish a new connection: [WinError 10061] 由于目标计算机积极拒绝，无法连接。')': /wd/hub/session
2020-09-15 19:07:35,536 - connectionpool.py [line:752] - WARNING: Retrying (Retry(total=0, connect=None, read=None, redirect=None, status=None)) after connection broken by 'NewConnectionError('<urllib3.connection.HTTPConnection object at 0x0000024E35BA6C88>: Failed to establish a new connection: [WinError 10061] 由于目标计算机积极拒绝，无法连接。')': /wd/hub/session
2020-09-15 19:08:25,664 - remote_connection.py [line:117] - INFO: Could not connect to port 4723 on host 127.0.0.1
2020-09-15 19:08:25,664 - remote_connection.py [line:136] - INFO: Could not get IP address for host: 127.0.0.1
2020-09-15 19:12:06,538 - TestMain.py [line:16] - INFO: app启动
2020-09-15 19:16:15,800 - TestMain.py [line:16] - INFO: app启动
2020-09-15 19:24:12,015 - connectionpool.py [line:752] - WARNING: Retrying (Retry(total=2, connect=None, read=None, redirect=None, status=None)) after connection broken by 'NewConnectionError('<urllib3.connection.HTTPConnection object at 0x00000223D7537A48>: Failed to establish a new connection: [Errno 11001] getaddrinfo failed')': //127.0.0.1:4723/wd/hub%22/session
2020-09-15 19:24:12,015 - connectionpool.py [line:752] - WARNING: Retrying (Retry(total=1, connect=None, read=None, redirect=None, status=None)) after connection broken by 'NewConnectionError('<urllib3.connection.HTTPConnection object at 0x00000223D755F608>: Failed to establish a new connection: [Errno 11001] getaddrinfo failed')': //127.0.0.1:4723/wd/hub%22/session
2020-09-15 19:24:12,016 - connectionpool.py [line:752] - WARNING: Retrying (Retry(total=0, connect=None, read=None, redirect=None, status=None)) after connection broken by 'NewConnectionError('<urllib3.connection.HTTPConnection object at 0x00000223D755FF08>: Failed to establish a new connection: [Errno 11001] getaddrinfo failed')': //127.0.0.1:4723/wd/hub%22/session
2020-09-15 19:25:07,917 - connectionpool.py [line:752] - WARNING: Retrying (Retry(total=2, connect=None, read=None, redirect=None, status=None)) after connection broken by 'NewConnectionError('<urllib3.connection.HTTPConnection object at 0x0000021C13CD2B08>: Failed to establish a new connection: [Errno 11001] getaddrinfo failed')': //127.0.0.1:4723/wd/hub%22/session
2020-09-15 19:25:07,917 - connectionpool.py [line:752] - WARNING: Retrying (Retry(total=1, connect=None, read=None, redirect=None, status=None)) after connection broken by 'NewConnectionError('<urllib3.connection.HTTPConnection object at 0x0000021C13CF2808>: Failed to establish a new connection: [Errno 11001] getaddrinfo failed')': //127.0.0.1:4723/wd/hub%22/session
2020-09-15 19:25:07,917 - connectionpool.py [line:752] - WARNING: Retrying (Retry(total=0, connect=None, read=None, redirect=None, status=None)) after connection broken by 'NewConnectionError('<urllib3.connection.HTTPConnection object at 0x0000021C13D0A048>: Failed to establish a new connection: [Errno 11001] getaddrinfo failed')': //127.0.0.1:4723/wd/hub%22/session
2020-09-15 19:25:51,630 - TestMain.py [line:16] - INFO: app启动
2020-09-15 19:27:46,250 - TestMain.py [line:16] - INFO: app启动
2020-09-15 19:59:05,341 - TestMain.py [line:16] - INFO: app启动
2020-09-15 19:59:15,885 - Appium.py [line:173] - ERROR: 按类查找元素失败！ 
2020-09-15 20:12:56,141 - remote_connection.py [line:117] - INFO: Could not connect to port 4723 on host 127.0.0.1
2020-09-15 20:12:56,141 - remote_connection.py [line:136] - INFO: Could not get IP address for host: 127.0.0.1
2020-09-15 20:12:58,144 - connectionpool.py [line:752] - WARNING: Retrying (Retry(total=2, connect=None, read=None, redirect=None, status=None)) after connection broken by 'NewConnectionError('<urllib3.connection.HTTPConnection object at 0x000001FA9E875548>: Failed to establish a new connection: [WinError 10061] 由于目标计算机积极拒绝，无法连接。')': /wd/hub/session
2020-09-15 20:13:00,146 - connectionpool.py [line:752] - WARNING: Retrying (Retry(total=1, connect=None, read=None, redirect=None, status=None)) after connection broken by 'NewConnectionError('<urllib3.connection.HTTPConnection object at 0x000001FA9E875F08>: Failed to establish a new connection: [WinError 10061] 由于目标计算机积极拒绝，无法连接。')': /wd/hub/session
2020-09-15 20:13:02,148 - connectionpool.py [line:752] - WARNING: Retrying (Retry(total=0, connect=None, read=None, redirect=None, status=None)) after connection broken by 'NewConnectionError('<urllib3.connection.HTTPConnection object at 0x000001FA9E8887C8>: Failed to establish a new connection: [WinError 10061] 由于目标计算机积极拒绝，无法连接。')': /wd/hub/session
2020-09-15 20:03:44,274 - TestMain.py [line:16] - INFO: app启动
2020-09-15 20:06:41,325 - remote_connection.py [line:117] - INFO: Could not connect to port 4723 on host 127.0.0.1
2020-09-15 20:06:41,325 - remote_connection.py [line:136] - INFO: Could not get IP address for host: 127.0.0.1
2020-09-15 20:06:43,333 - connectionpool.py [line:752] - WARNING: Retrying (Retry(total=2, connect=None, read=None, redirect=None, status=None)) after connection broken by 'NewConnectionError('<urllib3.connection.HTTPConnection object at 0x000001CFDEACAD48>: Failed to establish a new connection: [WinError 10061] 由于目标计算机积极拒绝，无法连接。')': /wd/hub/session
2020-09-15 20:06:45,336 - connectionpool.py [line:752] - WARNING: Retrying (Retry(total=1, connect=None, read=None, redirect=None, status=None)) after connection broken by 'NewConnectionError('<urllib3.connection.HTTPConnection object at 0x000001CFDEADE708>: Failed to establish a new connection: [WinError 10061] 由于目标计算机积极拒绝，无法连接。')': /wd/hub/session
2020-09-15 20:06:47,339 - connectionpool.py [line:752] - WARNING: Retrying (Retry(total=0, connect=None, read=None, redirect=None, status=None)) after connection broken by 'NewConnectionError('<urllib3.connection.HTTPConnection object at 0x000001CFDEADEF88>: Failed to establish a new connection: [WinError 10061] 由于目标计算机积极拒绝，无法连接。')': /wd/hub/session
2020-09-15 20:07:34,338 - TestMain.py [line:16] - INFO: app启动
2020-09-15 16:16:12,344 - SendEmali.py [line:14] - INFO: aaaa
2020-09-15 16:17:31,678 - SendEmali.py [line:106] - INFO: 邮件发送成功~！
2020-09-15 16:19:24,513 - SendEmali.py [line:106] - INFO: 邮件发送成功~！
2020-09-15 16:24:50,618 - SendEmali.py [line:106] - INFO: 邮件发送成功~！
2020-09-15 16:26:58,289 - SendEmali.py [line:106] - INFO: 邮件发送成功~！
2020-09-15 16:26:59,789 - SendEmali.py [line:106] - INFO: 邮件发送成功~！
2020-09-15 16:27:01,276 - SendEmali.py [line:106] - INFO: 邮件发送成功~！
2020-09-15 16:27:06,647 - SendEmali.py [line:106] - INFO: 邮件发送成功~！
2020-09-15 16:33:30,831 - SendEmali.py [line:106] - INFO: 邮件发送成功~！
2020-09-15 16:33:32,332 - SendEmali.py [line:106] - INFO: 邮件发送成功~！
2020-09-15 16:33:33,878 - SendEmali.py [line:106] - INFO: 邮件发送成功~！
2020-09-15 16:33:39,792 - SendEmali.py [line:106] - INFO: 邮件发送成功~！
2020-09-15 16:35:39,882 - SendEmali.py [line:106] - INFO: 邮件发送成功~！
2020-09-15 16:35:41,469 - SendEmali.py [line:106] - INFO: 邮件发送成功~！
2020-09-15 16:35:42,970 - SendEmali.py [line:106] - INFO: 邮件发送成功~！
2020-09-15 16:35:54,483 - SendEmali.py [line:106] - INFO: 邮件发送成功~！
