2020-11-06 16:00:10,415 - AdbTools.py [line:90] - ERROR: 请检查目标设备是否与主机连接成功！！！
2020-11-06 16:00:33,157 - AdbTools.py [line:90] - ERROR: 请检查目标设备是否与主机连接成功！！！
2020-11-06 16:08:56,923 - AdbTools.py [line:90] - ERROR: 请检查目标设备是否与主机连接成功！！！
2020-11-06 17:20:40,728 - AdbTools.py [line:27] - INFO: 检测到本地为Windows环境
2020-11-06 17:20:40,728 - AdbTools.py [line:46] - INFO: 上级所在目录为：D:\Work_Spaces\PyCharm_Project\AutoFramework
2020-11-06 17:20:40,821 - AdbTools.py [line:101] - ERROR: 请检查目标设备是否与主机连接成功！！！
2020-11-06 17:20:40,821 - AdbTools.py [line:82] - INFO: (1, "'aapt' 不是内部或外部命令，也不是可运行的程序\n或批处理文件。")
2020-11-06 17:24:23,200 - AdbTools.py [line:27] - INFO: 检测到本地为Windows环境
2020-11-06 17:24:23,200 - AdbTools.py [line:46] - INFO: 上级所在目录为：D:\Work_Spaces\PyCharm_Project\AutoFramework
2020-11-06 17:24:23,294 - AdbTools.py [line:107] - ERROR: 请检查目标设备是否与主机连接成功！！！
2020-11-06 17:24:23,309 - AdbTools.py [line:90] - ERROR: 'gbk' codec can't decode byte 0xae in position 3748: illegal multibyte sequence
2020-11-06 17:25:21,217 - AdbTools.py [line:27] - INFO: 检测到本地为Windows环境
2020-11-06 17:25:21,217 - AdbTools.py [line:46] - INFO: 上级所在目录为：D:\Work_Spaces\PyCharm_Project\AutoFramework
2020-11-06 17:25:21,374 - AdbTools.py [line:107] - ERROR: 请检查目标设备是否与主机连接成功！！！
2020-11-06 17:25:21,405 - AdbTools.py [line:88] - INFO: (1, "asset W 11-06 17:25:21 13604 12232 Asset path b'../ApkPath/app-release.apk' is neither a directory nor file (type=1).\nERROR: dump failed because assets could not be loaded")
2020-11-06 17:26:07,665 - AdbTools.py [line:27] - INFO: 检测到本地为Windows环境
2020-11-06 17:26:07,665 - AdbTools.py [line:46] - INFO: 上级所在目录为：D:\Work_Spaces\PyCharm_Project\AutoFramework
2020-11-06 17:26:07,758 - AdbTools.py [line:107] - ERROR: 请检查目标设备是否与主机连接成功！！！
2020-11-06 17:26:07,774 - AdbTools.py [line:88] - INFO: (1, "asset W 11-06 17:26:07 17848  3420 Asset path b'..\\\\ApkPath\\\\app-release.apk' is neither a directory nor file (type=1).\nERROR: dump failed because assets could not be loaded")
2020-11-06 17:26:12,841 - AdbTools.py [line:27] - INFO: 检测到本地为Windows环境
2020-11-06 17:26:12,841 - AdbTools.py [line:46] - INFO: 上级所在目录为：D:\Work_Spaces\PyCharm_Project\AutoFramework
2020-11-06 17:26:12,919 - AdbTools.py [line:107] - ERROR: 请检查目标设备是否与主机连接成功！！！
2020-11-06 17:26:12,966 - AdbTools.py [line:88] - INFO: (1, "asset W 11-06 17:26:12 12980  9308 Asset path b'../ApkPath/app-release.apk' is neither a directory nor file (type=1).\nERROR: dump failed because assets could not be loaded")
2020-11-06 17:26:41,212 - AdbTools.py [line:27] - INFO: 检测到本地为Windows环境
2020-11-06 17:26:41,212 - AdbTools.py [line:46] - INFO: 上级所在目录为：D:\Work_Spaces\PyCharm_Project\AutoFramework
2020-11-06 17:26:41,290 - AdbTools.py [line:107] - ERROR: 请检查目标设备是否与主机连接成功！！！
2020-11-06 17:26:41,321 - AdbTools.py [line:88] - INFO: (1, "asset W 11-06 17:26:41 17144 15000 Asset path b'D:\\\\Work_Spaces\\\\PyCharm_Project\\\\AutoFramework\\\\ApkPath\\\\app-release.apk' is neither a directory nor file (type=1).\nERROR: dump failed because assets could not be loaded")
2020-11-06 17:27:03,755 - AdbTools.py [line:27] - INFO: 检测到本地为Windows环境
2020-11-06 17:27:03,755 - AdbTools.py [line:46] - INFO: 上级所在目录为：D:\Work_Spaces\PyCharm_Project\AutoFramework
2020-11-06 17:27:03,849 - AdbTools.py [line:107] - ERROR: 请检查目标设备是否与主机连接成功！！！
2020-11-06 17:27:03,849 - AdbTools.py [line:90] - ERROR: chmod() missing required argument 'mode' (pos 2)
2020-11-06 17:28:02,145 - AdbTools.py [line:27] - INFO: 检测到本地为Windows环境
2020-11-06 17:28:02,145 - AdbTools.py [line:46] - INFO: 上级所在目录为：D:\Work_Spaces\PyCharm_Project\AutoFramework
2020-11-06 17:28:02,270 - AdbTools.py [line:107] - ERROR: 请检查目标设备是否与主机连接成功！！！
2020-11-06 17:28:02,270 - AdbTools.py [line:90] - ERROR: open() missing required argument 'flags' (pos 2)
2020-11-06 17:28:08,456 - AdbTools.py [line:27] - INFO: 检测到本地为Windows环境
2020-11-06 17:28:08,456 - AdbTools.py [line:46] - INFO: 上级所在目录为：D:\Work_Spaces\PyCharm_Project\AutoFramework
2020-11-06 17:28:08,534 - AdbTools.py [line:107] - ERROR: 请检查目标设备是否与主机连接成功！！！
2020-11-06 17:28:08,565 - AdbTools.py [line:88] - INFO: (1, "asset W 11-06 17:28:08  7816  2024 Asset path b'../ApkPath/app-release.apk' is neither a directory nor file (type=1).\nERROR: dump failed because assets could not be loaded")
2020-11-06 17:31:46,914 - AdbTools.py [line:27] - INFO: 检测到本地为Windows环境
2020-11-06 17:31:46,914 - AdbTools.py [line:46] - INFO: 上级所在目录为：D:\Work_Spaces\PyCharm_Project\AutoFramework
2020-11-06 17:31:47,008 - AdbTools.py [line:123] - ERROR: 请检查目标设备是否与主机连接成功！！！
2020-11-06 17:31:47,008 - AdbTools.py [line:106] - ERROR: can't get packageinfo
2020-11-06 17:32:10,999 - AdbTools.py [line:27] - INFO: 检测到本地为Windows环境
2020-11-06 17:32:10,999 - AdbTools.py [line:46] - INFO: 上级所在目录为：D:\Work_Spaces\PyCharm_Project\AutoFramework
2020-11-06 17:32:11,077 - AdbTools.py [line:123] - ERROR: 请检查目标设备是否与主机连接成功！！！
2020-11-06 17:32:11,077 - AdbTools.py [line:106] - ERROR: can't get packageinfo
2020-11-06 17:32:19,304 - AdbTools.py [line:27] - INFO: 检测到本地为Windows环境
2020-11-06 17:32:19,304 - AdbTools.py [line:46] - INFO: 上级所在目录为：D:\Work_Spaces\PyCharm_Project\AutoFramework
2020-11-06 17:32:19,382 - AdbTools.py [line:123] - ERROR: 请检查目标设备是否与主机连接成功！！！
2020-11-06 17:32:19,398 - AdbTools.py [line:106] - ERROR: can't get packageinfo
2020-11-06 17:32:23,455 - AdbTools.py [line:27] - INFO: 检测到本地为Windows环境
2020-11-06 17:32:23,455 - AdbTools.py [line:46] - INFO: 上级所在目录为：D:\Work_Spaces\PyCharm_Project\AutoFramework
2020-11-06 17:32:23,533 - AdbTools.py [line:123] - ERROR: 请检查目标设备是否与主机连接成功！！！
2020-11-06 17:32:23,533 - AdbTools.py [line:106] - ERROR: 'str' object has no attribute 'decode'
2020-11-06 17:32:52,396 - AdbTools.py [line:27] - INFO: 检测到本地为Windows环境
2020-11-06 17:32:52,396 - AdbTools.py [line:46] - INFO: 上级所在目录为：D:\Work_Spaces\PyCharm_Project\AutoFramework
2020-11-06 17:32:52,490 - AdbTools.py [line:108] - ERROR: 请检查目标设备是否与主机连接成功！！！
2020-11-06 17:32:52,490 - AdbTools.py [line:91] - ERROR: 'str' object has no attribute 'decode'
2020-11-06 17:32:59,171 - AdbTools.py [line:27] - INFO: 检测到本地为Windows环境
2020-11-06 17:32:59,171 - AdbTools.py [line:46] - INFO: 上级所在目录为：D:\Work_Spaces\PyCharm_Project\AutoFramework
2020-11-06 17:32:59,249 - AdbTools.py [line:108] - ERROR: 请检查目标设备是否与主机连接成功！！！
2020-11-06 17:33:07,883 - AdbTools.py [line:27] - INFO: 检测到本地为Windows环境
2020-11-06 17:33:07,883 - AdbTools.py [line:46] - INFO: 上级所在目录为：D:\Work_Spaces\PyCharm_Project\AutoFramework
2020-11-06 17:33:07,961 - AdbTools.py [line:108] - ERROR: 请检查目标设备是否与主机连接成功！！！
2020-11-06 17:33:07,993 - AdbTools.py [line:91] - ERROR: 'gbk' codec can't decode byte 0xae in position 3748: illegal multibyte sequence
2020-11-06 17:33:22,372 - AdbTools.py [line:27] - INFO: 检测到本地为Windows环境
2020-11-06 17:33:22,372 - AdbTools.py [line:46] - INFO: 上级所在目录为：D:\Work_Spaces\PyCharm_Project\AutoFramework
2020-11-06 17:33:22,451 - AdbTools.py [line:108] - ERROR: 请检查目标设备是否与主机连接成功！！！
2020-11-06 17:33:22,466 - AdbTools.py [line:91] - ERROR: 'gbk' codec can't decode byte 0xae in position 3748: illegal multibyte sequence
2020-11-06 17:33:31,006 - AdbTools.py [line:27] - INFO: 检测到本地为Windows环境
2020-11-06 17:33:31,006 - AdbTools.py [line:46] - INFO: 上级所在目录为：D:\Work_Spaces\PyCharm_Project\AutoFramework
2020-11-06 17:33:31,099 - AdbTools.py [line:108] - ERROR: 请检查目标设备是否与主机连接成功！！！
2020-11-06 17:33:31,099 - AdbTools.py [line:91] - ERROR: 'str' object has no attribute 'decode'
2020-11-06 17:33:51,694 - AdbTools.py [line:27] - INFO: 检测到本地为Windows环境
2020-11-06 17:33:51,694 - AdbTools.py [line:46] - INFO: 上级所在目录为：D:\Work_Spaces\PyCharm_Project\AutoFramework
2020-11-06 17:33:51,772 - AdbTools.py [line:108] - ERROR: 请检查目标设备是否与主机连接成功！！！
2020-11-06 17:33:51,807 - AdbTools.py [line:91] - ERROR: 'gbk' codec can't decode byte 0xae in position 3748: illegal multibyte sequence
2020-11-06 17:34:06,650 - AdbTools.py [line:27] - INFO: 检测到本地为Windows环境
2020-11-06 17:34:06,650 - AdbTools.py [line:46] - INFO: 上级所在目录为：D:\Work_Spaces\PyCharm_Project\AutoFramework
2020-11-06 17:34:06,729 - AdbTools.py [line:123] - ERROR: 请检查目标设备是否与主机连接成功！！！
2020-11-06 17:34:06,744 - AdbTools.py [line:106] - ERROR: 'gbk' codec can't decode byte 0xae in position 3748: illegal multibyte sequence
2020-11-06 17:34:27,907 - AdbTools.py [line:27] - INFO: 检测到本地为Windows环境
2020-11-06 17:34:27,907 - AdbTools.py [line:46] - INFO: 上级所在目录为：D:\Work_Spaces\PyCharm_Project\AutoFramework
2020-11-06 17:34:27,985 - AdbTools.py [line:123] - ERROR: 请检查目标设备是否与主机连接成功！！！
2020-11-06 17:34:28,001 - AdbTools.py [line:106] - ERROR: can't get packageinfo
2020-11-06 17:39:01,657 - AdbTools.py [line:27] - INFO: 检测到本地为Windows环境
2020-11-06 17:39:01,657 - AdbTools.py [line:46] - INFO: 上级所在目录为：D:\Work_Spaces\PyCharm_Project\AutoFramework
2020-11-06 17:39:01,751 - AdbTools.py [line:117] - ERROR: 请检查目标设备是否与主机连接成功！！！
2020-11-06 17:39:01,751 - AdbTools.py [line:100] - ERROR: can't get packageinfo
2020-11-06 17:39:11,710 - AdbTools.py [line:27] - INFO: 检测到本地为Windows环境
2020-11-06 17:39:11,710 - AdbTools.py [line:46] - INFO: 上级所在目录为：D:\Work_Spaces\PyCharm_Project\AutoFramework
2020-11-06 17:39:11,788 - AdbTools.py [line:117] - ERROR: 请检查目标设备是否与主机连接成功！！！
2020-11-06 17:39:11,803 - AdbTools.py [line:100] - ERROR: can't get packageinfo
2020-11-06 17:39:19,820 - AdbTools.py [line:27] - INFO: 检测到本地为Windows环境
2020-11-06 17:39:19,820 - AdbTools.py [line:46] - INFO: 上级所在目录为：D:\Work_Spaces\PyCharm_Project\AutoFramework
2020-11-06 17:39:19,852 - AdbTools.py [line:100] - ERROR: can't get packageinfo
2020-11-06 17:39:31,445 - AdbTools.py [line:27] - INFO: 检测到本地为Windows环境
2020-11-06 17:39:31,445 - AdbTools.py [line:46] - INFO: 上级所在目录为：D:\Work_Spaces\PyCharm_Project\AutoFramework
2020-11-06 17:39:31,476 - AdbTools.py [line:99] - ERROR: can't get packageinfo
2020-11-06 17:39:40,138 - AdbTools.py [line:27] - INFO: 检测到本地为Windows环境
2020-11-06 17:39:40,138 - AdbTools.py [line:46] - INFO: 上级所在目录为：D:\Work_Spaces\PyCharm_Project\AutoFramework
2020-11-06 17:39:40,185 - AdbTools.py [line:98] - ERROR: can't get packageinfo
2020-11-06 17:40:43,945 - AdbTools.py [line:27] - INFO: 检测到本地为Windows环境
2020-11-06 17:40:43,945 - AdbTools.py [line:46] - INFO: 上级所在目录为：D:\Work_Spaces\PyCharm_Project\AutoFramework
2020-11-06 17:40:44,008 - AdbTools.py [line:99] - ERROR: 'gbk' codec can't decode byte 0xae in position 3748: illegal multibyte sequence
2020-11-06 17:41:04,055 - AdbTools.py [line:27] - INFO: 检测到本地为Windows环境
2020-11-06 17:41:04,055 - AdbTools.py [line:46] - INFO: 上级所在目录为：D:\Work_Spaces\PyCharm_Project\AutoFramework
2020-11-06 17:41:04,102 - AdbTools.py [line:99] - ERROR: 'gbk' codec can't decode byte 0xae in position 3748: illegal multibyte sequence
2020-11-06 17:42:08,687 - AdbTools.py [line:27] - INFO: 检测到本地为Windows环境
2020-11-06 17:42:08,687 - AdbTools.py [line:46] - INFO: 上级所在目录为：D:\Work_Spaces\PyCharm_Project\AutoFramework
2020-11-06 17:42:08,733 - AdbTools.py [line:99] - ERROR: 'gbk' codec can't decode byte 0xae in position 3748: illegal multibyte sequence
2020-11-06 17:42:15,024 - AdbTools.py [line:27] - INFO: 检测到本地为Windows环境
2020-11-06 17:42:15,024 - AdbTools.py [line:46] - INFO: 上级所在目录为：D:\Work_Spaces\PyCharm_Project\AutoFramework
2020-11-06 17:42:15,086 - AdbTools.py [line:99] - ERROR: 'gbk' codec can't decode byte 0xae in position 3748: illegal multibyte sequence
2020-11-06 17:42:25,643 - AdbTools.py [line:27] - INFO: 检测到本地为Windows环境
2020-11-06 17:42:25,643 - AdbTools.py [line:46] - INFO: 上级所在目录为：D:\Work_Spaces\PyCharm_Project\AutoFramework
2020-11-06 17:42:25,690 - AdbTools.py [line:100] - ERROR: 'gbk' codec can't decode byte 0xae in position 3748: illegal multibyte sequence
2020-11-06 17:44:08,932 - AdbTools.py [line:27] - INFO: 检测到本地为Windows环境
2020-11-06 17:44:08,947 - AdbTools.py [line:46] - INFO: 上级所在目录为：D:\Work_Spaces\PyCharm_Project\AutoFramework
2020-11-06 17:44:08,963 - AdbTools.py [line:99] - ERROR: '_io.TextIOWrapper' object has no attribute 'readall'
2020-11-06 17:44:18,012 - AdbTools.py [line:27] - INFO: 检测到本地为Windows环境
2020-11-06 17:44:18,012 - AdbTools.py [line:46] - INFO: 上级所在目录为：D:\Work_Spaces\PyCharm_Project\AutoFramework
2020-11-06 17:44:18,059 - AdbTools.py [line:99] - ERROR: 'gbk' codec can't decode byte 0xae in position 3748: illegal multibyte sequence
2020-11-06 17:44:21,340 - AdbTools.py [line:27] - INFO: 检测到本地为Windows环境
2020-11-06 17:44:21,340 - AdbTools.py [line:46] - INFO: 上级所在目录为：D:\Work_Spaces\PyCharm_Project\AutoFramework
2020-11-06 17:44:21,386 - AdbTools.py [line:99] - ERROR: 'gbk' codec can't decode byte 0xae in position 3748: illegal multibyte sequence
2020-11-06 17:44:50,899 - AdbTools.py [line:27] - INFO: 检测到本地为Windows环境
2020-11-06 17:44:50,899 - AdbTools.py [line:46] - INFO: 上级所在目录为：D:\Work_Spaces\PyCharm_Project\AutoFramework
2020-11-06 17:44:50,945 - AdbTools.py [line:99] - ERROR: 'gbk' codec can't decode byte 0xae in position 3748: illegal multibyte sequence
2020-11-06 17:45:01,017 - AdbTools.py [line:27] - INFO: 检测到本地为Windows环境
2020-11-06 17:45:01,017 - AdbTools.py [line:46] - INFO: 上级所在目录为：D:\Work_Spaces\PyCharm_Project\AutoFramework
2020-11-06 17:45:01,064 - AdbTools.py [line:99] - ERROR: 'gbk' codec can't decode byte 0xae in position 3748: illegal multibyte sequence
2020-11-06 17:45:23,530 - AdbTools.py [line:27] - INFO: 检测到本地为Windows环境
2020-11-06 17:45:23,530 - AdbTools.py [line:46] - INFO: 上级所在目录为：D:\Work_Spaces\PyCharm_Project\AutoFramework
2020-11-06 17:45:23,576 - AdbTools.py [line:97] - ERROR: 'gbk' codec can't decode byte 0xae in position 3748: illegal multibyte sequence
2020-11-06 17:47:03,808 - AdbTools.py [line:27] - INFO: 检测到本地为Windows环境
2020-11-06 17:47:03,808 - AdbTools.py [line:46] - INFO: 上级所在目录为：D:\Work_Spaces\PyCharm_Project\AutoFramework
2020-11-06 17:47:03,839 - AdbTools.py [line:104] - ERROR: type object 'AdbManage' has no attribute 'apkPath'
2020-11-06 17:47:16,696 - AdbTools.py [line:27] - INFO: 检测到本地为Windows环境
2020-11-06 17:47:16,696 - AdbTools.py [line:46] - INFO: 上级所在目录为：D:\Work_Spaces\PyCharm_Project\AutoFramework
2020-11-06 17:48:22,847 - AdbTools.py [line:27] - INFO: 检测到本地为Windows环境
2020-11-06 17:48:22,847 - AdbTools.py [line:46] - INFO: 上级所在目录为：D:\Work_Spaces\PyCharm_Project\AutoFramework
2020-11-06 17:48:22,894 - AdbTools.py [line:104] - ERROR: can't get packageinfo
2020-11-06 17:48:27,869 - AdbTools.py [line:27] - INFO: 检测到本地为Windows环境
2020-11-06 17:48:27,869 - AdbTools.py [line:46] - INFO: 上级所在目录为：D:\Work_Spaces\PyCharm_Project\AutoFramework
2020-11-06 17:48:27,916 - AdbTools.py [line:104] - ERROR: can't get packageinfo
2020-11-06 17:48:36,818 - AdbTools.py [line:27] - INFO: 检测到本地为Windows环境
2020-11-06 17:48:36,818 - AdbTools.py [line:46] - INFO: 上级所在目录为：D:\Work_Spaces\PyCharm_Project\AutoFramework
2020-11-06 17:48:36,865 - AdbTools.py [line:104] - ERROR: can't get packageinfo
2020-11-06 17:48:49,548 - AdbTools.py [line:27] - INFO: 检测到本地为Windows环境
2020-11-06 17:48:49,548 - AdbTools.py [line:46] - INFO: 上级所在目录为：D:\Work_Spaces\PyCharm_Project\AutoFramework
2020-11-06 17:49:02,831 - AdbTools.py [line:27] - INFO: 检测到本地为Windows环境
2020-11-06 17:49:02,831 - AdbTools.py [line:46] - INFO: 上级所在目录为：D:\Work_Spaces\PyCharm_Project\AutoFramework
2020-11-06 17:49:02,893 - AdbTools.py [line:104] - ERROR: can't get packageinfo
2020-11-06 17:49:09,612 - AdbTools.py [line:27] - INFO: 检测到本地为Windows环境
2020-11-06 17:49:09,612 - AdbTools.py [line:46] - INFO: 上级所在目录为：D:\Work_Spaces\PyCharm_Project\AutoFramework
2020-11-06 17:49:09,659 - AdbTools.py [line:104] - ERROR: can't get packageinfo
2020-11-06 17:49:22,222 - AdbTools.py [line:27] - INFO: 检测到本地为Windows环境
2020-11-06 17:49:22,222 - AdbTools.py [line:46] - INFO: 上级所在目录为：D:\Work_Spaces\PyCharm_Project\AutoFramework
2020-11-06 17:51:35,565 - AdbTools.py [line:27] - INFO: 检测到本地为Windows环境
2020-11-06 17:51:35,565 - AdbTools.py [line:46] - INFO: 上级所在目录为：D:\Work_Spaces\PyCharm_Project\AutoFramework
2020-11-06 17:52:02,309 - AdbTools.py [line:27] - INFO: 检测到本地为Windows环境
2020-11-06 17:52:02,309 - AdbTools.py [line:46] - INFO: 上级所在目录为：D:\Work_Spaces\PyCharm_Project\AutoFramework
2020-11-06 17:52:02,371 - AdbTools.py [line:99] - INFO: packagename:com.tencent.now
2020-11-06 17:52:02,371 - AdbTools.py [line:100] - INFO: versionCode:2473
2020-11-06 17:52:02,371 - AdbTools.py [line:101] - INFO: versionName:1.54.7.26
2020-11-06 17:52:37,823 - AdbTools.py [line:27] - INFO: 检测到本地为Windows环境
2020-11-06 17:52:37,823 - AdbTools.py [line:46] - INFO: 上级所在目录为：D:\Work_Spaces\PyCharm_Project\AutoFramework
2020-11-06 17:52:37,870 - AdbTools.py [line:99] - INFO: packagename:com.tencent.now
2020-11-06 17:52:37,870 - AdbTools.py [line:100] - INFO: versionCode:2473
2020-11-06 17:52:37,870 - AdbTools.py [line:101] - INFO: versionName:1.54.7.26
2020-11-06 17:53:33,219 - AdbTools.py [line:27] - INFO: 检测到本地为Windows环境
2020-11-06 17:53:33,219 - AdbTools.py [line:46] - INFO: 上级所在目录为：D:\Work_Spaces\PyCharm_Project\AutoFramework
2020-11-06 17:53:33,266 - AdbTools.py [line:99] - INFO: PackageName:com.tencent.now
2020-11-06 17:53:33,266 - AdbTools.py [line:100] - INFO: VersionCode:2473
2020-11-06 17:53:33,266 - AdbTools.py [line:101] - INFO: VersionName:1.54.7.26
2020-11-06 17:53:42,726 - AdbTools.py [line:27] - INFO: 检测到本地为Windows环境
2020-11-06 17:53:42,726 - AdbTools.py [line:46] - INFO: 上级所在目录为：D:\Work_Spaces\PyCharm_Project\AutoFramework
2020-11-06 17:53:42,788 - AdbTools.py [line:99] - INFO: PackageName：com.tencent.now
2020-11-06 17:53:42,788 - AdbTools.py [line:100] - INFO: VersionCode：2473
2020-11-06 17:53:42,788 - AdbTools.py [line:101] - INFO: VersionName：1.54.7.26
2020-11-06 17:59:55,839 - Appium.py [line:34] - ERROR: 应用程序选择初始失败！
2020-11-06 17:59:56,840 - remote_connection.py [line:117] - INFO: Could not connect to port 4723 on host 127.0.0.1
2020-11-06 17:59:56,840 - remote_connection.py [line:136] - INFO: Could not get IP address for host: 127.0.0.1
2020-11-06 17:59:58,870 - connectionpool.py [line:752] - WARNING: Retrying (Retry(total=2, connect=None, read=None, redirect=None, status=None)) after connection broken by 'NewConnectionError('<urllib3.connection.HTTPConnection object at 0x0000019F97017F60>: Failed to establish a new connection: [WinError 10061] 由于目标计算机积极拒绝，无法连接。')': /wd/hub/session
2020-11-06 18:00:00,882 - connectionpool.py [line:752] - WARNING: Retrying (Retry(total=1, connect=None, read=None, redirect=None, status=None)) after connection broken by 'NewConnectionError('<urllib3.connection.HTTPConnection object at 0x0000019F9702B0F0>: Failed to establish a new connection: [WinError 10061] 由于目标计算机积极拒绝，无法连接。')': /wd/hub/session
2020-11-06 18:00:02,902 - connectionpool.py [line:752] - WARNING: Retrying (Retry(total=0, connect=None, read=None, redirect=None, status=None)) after connection broken by 'NewConnectionError('<urllib3.connection.HTTPConnection object at 0x0000019F9702B240>: Failed to establish a new connection: [WinError 10061] 由于目标计算机积极拒绝，无法连接。')': /wd/hub/session
2020-11-06 18:07:02,955 - Appium.py [line:34] - ERROR: 应用程序选择初始失败！
2020-11-06 18:07:03,986 - remote_connection.py [line:117] - INFO: Could not connect to port 4723 on host 127.0.0.1
2020-11-06 18:07:03,986 - remote_connection.py [line:136] - INFO: Could not get IP address for host: 127.0.0.1
2020-11-06 18:07:06,037 - connectionpool.py [line:752] - WARNING: Retrying (Retry(total=2, connect=None, read=None, redirect=None, status=None)) after connection broken by 'NewConnectionError('<urllib3.connection.HTTPConnection object at 0x00000247DEF27EF0>: Failed to establish a new connection: [WinError 10061] 由于目标计算机积极拒绝，无法连接。')': /wd/hub/session
2020-11-06 18:07:08,086 - connectionpool.py [line:752] - WARNING: Retrying (Retry(total=1, connect=None, read=None, redirect=None, status=None)) after connection broken by 'NewConnectionError('<urllib3.connection.HTTPConnection object at 0x00000247DEF3F080>: Failed to establish a new connection: [WinError 10061] 由于目标计算机积极拒绝，无法连接。')': /wd/hub/session
2020-11-06 18:07:10,128 - connectionpool.py [line:752] - WARNING: Retrying (Retry(total=0, connect=None, read=None, redirect=None, status=None)) after connection broken by 'NewConnectionError('<urllib3.connection.HTTPConnection object at 0x00000247DEF3F128>: Failed to establish a new connection: [WinError 10061] 由于目标计算机积极拒绝，无法连接。')': /wd/hub/session
2020-11-06 18:07:23,763 - Appium.py [line:35] - ERROR: 应用程序选择初始失败！
2020-11-06 18:07:24,764 - remote_connection.py [line:117] - INFO: Could not connect to port 4723 on host 127.0.0.1
2020-11-06 18:07:24,764 - remote_connection.py [line:136] - INFO: Could not get IP address for host: 127.0.0.1
2020-11-06 18:07:26,800 - connectionpool.py [line:752] - WARNING: Retrying (Retry(total=2, connect=None, read=None, redirect=None, status=None)) after connection broken by 'NewConnectionError('<urllib3.connection.HTTPConnection object at 0x00000188B1937EF0>: Failed to establish a new connection: [WinError 10061] 由于目标计算机积极拒绝，无法连接。')': /wd/hub/session
2020-11-06 18:07:28,847 - connectionpool.py [line:752] - WARNING: Retrying (Retry(total=1, connect=None, read=None, redirect=None, status=None)) after connection broken by 'NewConnectionError('<urllib3.connection.HTTPConnection object at 0x00000188B194F080>: Failed to establish a new connection: [WinError 10061] 由于目标计算机积极拒绝，无法连接。')': /wd/hub/session
2020-11-06 18:07:30,851 - connectionpool.py [line:752] - WARNING: Retrying (Retry(total=0, connect=None, read=None, redirect=None, status=None)) after connection broken by 'NewConnectionError('<urllib3.connection.HTTPConnection object at 0x00000188B194F198>: Failed to establish a new connection: [WinError 10061] 由于目标计算机积极拒绝，无法连接。')': /wd/hub/session
2020-11-06 18:07:52,621 - Appium.py [line:34] - ERROR: 应用程序选择初始失败！
2020-11-06 18:08:17,845 - Appium.py [line:34] - ERROR: 应用程序选择初始失败！
2020-11-06 18:08:48,474 - Appium.py [line:34] - ERROR: 应用程序选择初始失败！
2020-11-06 18:16:03,397 - remote_connection.py [line:117] - INFO: Could not connect to port 4723 on host 127.0.0.1
2020-11-06 18:16:03,397 - remote_connection.py [line:136] - INFO: Could not get IP address for host: 127.0.0.1
2020-11-06 18:16:05,419 - connectionpool.py [line:752] - WARNING: Retrying (Retry(total=2, connect=None, read=None, redirect=None, status=None)) after connection broken by 'NewConnectionError('<urllib3.connection.HTTPConnection object at 0x0000020183E83F28>: Failed to establish a new connection: [WinError 10061] 由于目标计算机积极拒绝，无法连接。')': /wd/hub/session
2020-11-06 18:16:07,428 - connectionpool.py [line:752] - WARNING: Retrying (Retry(total=1, connect=None, read=None, redirect=None, status=None)) after connection broken by 'NewConnectionError('<urllib3.connection.HTTPConnection object at 0x0000020183EB00B8>: Failed to establish a new connection: [WinError 10061] 由于目标计算机积极拒绝，无法连接。')': /wd/hub/session
2020-11-06 18:16:09,451 - connectionpool.py [line:752] - WARNING: Retrying (Retry(total=0, connect=None, read=None, redirect=None, status=None)) after connection broken by 'NewConnectionError('<urllib3.connection.HTTPConnection object at 0x0000020183EB01D0>: Failed to establish a new connection: [WinError 10061] 由于目标计算机积极拒绝，无法连接。')': /wd/hub/session
2020-11-06 18:18:16,609 - remote_connection.py [line:117] - INFO: Could not connect to port 4723 on host 127.0.0.1
2020-11-06 18:18:16,609 - remote_connection.py [line:136] - INFO: Could not get IP address for host: 127.0.0.1
2020-11-06 18:18:18,630 - connectionpool.py [line:752] - WARNING: Retrying (Retry(total=2, connect=None, read=None, redirect=None, status=None)) after connection broken by 'NewConnectionError('<urllib3.connection.HTTPConnection object at 0x0000027C482E3FD0>: Failed to establish a new connection: [WinError 10061] 由于目标计算机积极拒绝，无法连接。')': /wd/hub/session
2020-11-06 18:18:20,665 - connectionpool.py [line:752] - WARNING: Retrying (Retry(total=1, connect=None, read=None, redirect=None, status=None)) after connection broken by 'NewConnectionError('<urllib3.connection.HTTPConnection object at 0x0000027C482F90F0>: Failed to establish a new connection: [WinError 10061] 由于目标计算机积极拒绝，无法连接。')': /wd/hub/session
2020-11-06 18:18:22,683 - connectionpool.py [line:752] - WARNING: Retrying (Retry(total=0, connect=None, read=None, redirect=None, status=None)) after connection broken by 'NewConnectionError('<urllib3.connection.HTTPConnection object at 0x0000027C482F9278>: Failed to establish a new connection: [WinError 10061] 由于目标计算机积极拒绝，无法连接。')': /wd/hub/session
2020-11-06 18:18:28,449 - remote_connection.py [line:117] - INFO: Could not connect to port 4723 on host 127.0.0.1
2020-11-06 18:18:28,449 - remote_connection.py [line:136] - INFO: Could not get IP address for host: 127.0.0.1
2020-11-06 18:18:30,459 - connectionpool.py [line:752] - WARNING: Retrying (Retry(total=2, connect=None, read=None, redirect=None, status=None)) after connection broken by 'NewConnectionError('<urllib3.connection.HTTPConnection object at 0x000001DFEACF3FD0>: Failed to establish a new connection: [WinError 10061] 由于目标计算机积极拒绝，无法连接。')': /wd/hub/session
2020-11-06 18:18:32,491 - connectionpool.py [line:752] - WARNING: Retrying (Retry(total=1, connect=None, read=None, redirect=None, status=None)) after connection broken by 'NewConnectionError('<urllib3.connection.HTTPConnection object at 0x000001DFEAD0A0F0>: Failed to establish a new connection: [WinError 10061] 由于目标计算机积极拒绝，无法连接。')': /wd/hub/session
2020-11-06 18:18:34,496 - connectionpool.py [line:752] - WARNING: Retrying (Retry(total=0, connect=None, read=None, redirect=None, status=None)) after connection broken by 'NewConnectionError('<urllib3.connection.HTTPConnection object at 0x000001DFEAD0A278>: Failed to establish a new connection: [WinError 10061] 由于目标计算机积极拒绝，无法连接。')': /wd/hub/session
2020-11-06 18:38:13,533 - connectionpool.py [line:752] - WARNING: Retrying (Retry(total=2, connect=None, read=None, redirect=None, status=None)) after connection broken by 'NewConnectionError('<urllib3.connection.HTTPConnection object at 0x000001E94B6E79B0>: Failed to establish a new connection: [Errno 11001] getaddrinfo failed')': //127.0.0.1:4723/wd/hub','http://127.0.0.1:4724/wd/hub'/session
2020-11-06 18:38:13,533 - connectionpool.py [line:752] - WARNING: Retrying (Retry(total=1, connect=None, read=None, redirect=None, status=None)) after connection broken by 'NewConnectionError('<urllib3.connection.HTTPConnection object at 0x000001E94B6E7BA8>: Failed to establish a new connection: [Errno 11001] getaddrinfo failed')': //127.0.0.1:4723/wd/hub','http://127.0.0.1:4724/wd/hub'/session
2020-11-06 18:38:13,533 - connectionpool.py [line:752] - WARNING: Retrying (Retry(total=0, connect=None, read=None, redirect=None, status=None)) after connection broken by 'NewConnectionError('<urllib3.connection.HTTPConnection object at 0x000001E94B6F7080>: Failed to establish a new connection: [Errno 11001] getaddrinfo failed')': //127.0.0.1:4723/wd/hub','http://127.0.0.1:4724/wd/hub'/session
2020-11-06 18:39:45,159 - connectionpool.py [line:752] - WARNING: Retrying (Retry(total=2, connect=None, read=None, redirect=None, status=None)) after connection broken by 'NewConnectionError('<urllib3.connection.HTTPConnection object at 0x0000022E0CC47978>: Failed to establish a new connection: [Errno 11001] getaddrinfo failed')': //127.0.0.1:4723/wd/hub','http://127.0.0.1:4724/wd/hub'/session
2020-11-06 18:39:45,160 - connectionpool.py [line:752] - WARNING: Retrying (Retry(total=1, connect=None, read=None, redirect=None, status=None)) after connection broken by 'NewConnectionError('<urllib3.connection.HTTPConnection object at 0x0000022E0CC47E80>: Failed to establish a new connection: [Errno 11001] getaddrinfo failed')': //127.0.0.1:4723/wd/hub','http://127.0.0.1:4724/wd/hub'/session
2020-11-06 18:39:45,160 - connectionpool.py [line:752] - WARNING: Retrying (Retry(total=0, connect=None, read=None, redirect=None, status=None)) after connection broken by 'NewConnectionError('<urllib3.connection.HTTPConnection object at 0x0000022E0CC57048>: Failed to establish a new connection: [Errno 11001] getaddrinfo failed')': //127.0.0.1:4723/wd/hub','http://127.0.0.1:4724/wd/hub'/session
2020-11-06 18:40:12,428 - connectionpool.py [line:752] - WARNING: Retrying (Retry(total=2, connect=None, read=None, redirect=None, status=None)) after connection broken by 'NewConnectionError('<urllib3.connection.HTTPConnection object at 0x00000289A39869B0>: Failed to establish a new connection: [Errno 11001] getaddrinfo failed')': //127.0.0.1:4723/wd/hub','http://127.0.0.1:4724/wd/hub'/session
2020-11-06 18:40:12,439 - connectionpool.py [line:752] - WARNING: Retrying (Retry(total=1, connect=None, read=None, redirect=None, status=None)) after connection broken by 'NewConnectionError('<urllib3.connection.HTTPConnection object at 0x00000289A3986BA8>: Failed to establish a new connection: [Errno 11001] getaddrinfo failed')': //127.0.0.1:4723/wd/hub','http://127.0.0.1:4724/wd/hub'/session
2020-11-06 18:40:12,439 - connectionpool.py [line:752] - WARNING: Retrying (Retry(total=0, connect=None, read=None, redirect=None, status=None)) after connection broken by 'NewConnectionError('<urllib3.connection.HTTPConnection object at 0x00000289A3997080>: Failed to establish a new connection: [Errno 11001] getaddrinfo failed')': //127.0.0.1:4723/wd/hub','http://127.0.0.1:4724/wd/hub'/session
2020-11-06 18:44:08,849 - remote_connection.py [line:117] - INFO: Could not connect to port 4723 on host 127.0.0.1
2020-11-06 18:44:08,849 - remote_connection.py [line:136] - INFO: Could not get IP address for host: 127.0.0.1
2020-11-06 18:44:10,883 - connectionpool.py [line:752] - WARNING: Retrying (Retry(total=2, connect=None, read=None, redirect=None, status=None)) after connection broken by 'NewConnectionError('<urllib3.connection.HTTPConnection object at 0x000001C3449B1E80>: Failed to establish a new connection: [WinError 10061] 由于目标计算机积极拒绝，无法连接。')': /wd/hub/session
2020-11-06 18:44:12,936 - connectionpool.py [line:752] - WARNING: Retrying (Retry(total=1, connect=None, read=None, redirect=None, status=None)) after connection broken by 'NewConnectionError('<urllib3.connection.HTTPConnection object at 0x000001C3449B1F60>: Failed to establish a new connection: [WinError 10061] 由于目标计算机积极拒绝，无法连接。')': /wd/hub/session
2020-11-06 18:44:14,965 - connectionpool.py [line:752] - WARNING: Retrying (Retry(total=0, connect=None, read=None, redirect=None, status=None)) after connection broken by 'NewConnectionError('<urllib3.connection.HTTPConnection object at 0x000001C3449E0128>: Failed to establish a new connection: [WinError 10061] 由于目标计算机积极拒绝，无法连接。')': /wd/hub/session
2020-11-06 18:54:14,268 - remote_connection.py [line:117] - INFO: Could not connect to port 4724 on host 127.0.0.1
2020-11-06 18:54:14,268 - remote_connection.py [line:136] - INFO: Could not get IP address for host: 127.0.0.1
2020-11-06 18:54:16,298 - connectionpool.py [line:752] - WARNING: Retrying (Retry(total=2, connect=None, read=None, redirect=None, status=None)) after connection broken by 'NewConnectionError('<urllib3.connection.HTTPConnection object at 0x0000024E072D8860>: Failed to establish a new connection: [WinError 10061] 由于目标计算机积极拒绝，无法连接。')': /wd/hub/session
2020-11-06 18:54:18,325 - connectionpool.py [line:752] - WARNING: Retrying (Retry(total=1, connect=None, read=None, redirect=None, status=None)) after connection broken by 'NewConnectionError('<urllib3.connection.HTTPConnection object at 0x0000024E072D8940>: Failed to establish a new connection: [WinError 10061] 由于目标计算机积极拒绝，无法连接。')': /wd/hub/session
2020-11-06 18:54:20,372 - connectionpool.py [line:752] - WARNING: Retrying (Retry(total=0, connect=None, read=None, redirect=None, status=None)) after connection broken by 'NewConnectionError('<urllib3.connection.HTTPConnection object at 0x0000024E072D8AC8>: Failed to establish a new connection: [WinError 10061] 由于目标计算机积极拒绝，无法连接。')': /wd/hub/session
2020-11-06 19:26:49,440 - GetDeviceMsgs.py [line:38] - INFO: 处理后获取的设备版本号为：9
2020-11-06 19:26:49,533 - GetDeviceMsgs.py [line:38] - INFO: 处理后获取的设备版本号为：9
2020-11-06 19:27:33,198 - GetDeviceMsgs.py [line:37] - INFO: adb命令获取的设备版本号为：['9\n']
2020-11-06 19:27:33,198 - GetDeviceMsgs.py [line:38] - INFO: 处理后获取的设备版本号为：9
2020-11-06 19:27:33,277 - GetDeviceMsgs.py [line:37] - INFO: adb命令获取的设备版本号为：['9\n']
2020-11-06 19:27:33,277 - GetDeviceMsgs.py [line:38] - INFO: 处理后获取的设备版本号为：9
2020-11-06 19:27:52,117 - GetDeviceMsgs.py [line:37] - INFO: adb命令获取的设备版本号为：['9\n']
2020-11-06 19:27:52,117 - GetDeviceMsgs.py [line:38] - INFO: 处理后获取的设备版本号为：9
2020-11-06 19:27:52,180 - GetDeviceMsgs.py [line:37] - INFO: adb命令获取的设备版本号为：['9\n']
2020-11-06 19:27:52,180 - GetDeviceMsgs.py [line:38] - INFO: 处理后获取的设备版本号为：9
2020-11-06 19:28:37,779 - GetDeviceMsgs.py [line:36] - INFO: 处理后获取的设备版本号为：9
2020-11-06 19:28:37,826 - GetDeviceMsgs.py [line:36] - INFO: 处理后获取的设备版本号为：9
2020-11-06 19:30:12,297 - remote_connection.py [line:117] - INFO: Could not connect to port 4723 on host 127.0.0.1
2020-11-06 19:30:12,297 - remote_connection.py [line:136] - INFO: Could not get IP address for host: 127.0.0.1
2020-11-06 19:30:14,325 - connectionpool.py [line:752] - WARNING: Retrying (Retry(total=2, connect=None, read=None, redirect=None, status=None)) after connection broken by 'NewConnectionError('<urllib3.connection.HTTPConnection object at 0x000001ABF6B91F60>: Failed to establish a new connection: [WinError 10061] 由于目标计算机积极拒绝，无法连接。')': /wd/hub/session
2020-11-06 19:30:16,345 - connectionpool.py [line:752] - WARNING: Retrying (Retry(total=1, connect=None, read=None, redirect=None, status=None)) after connection broken by 'NewConnectionError('<urllib3.connection.HTTPConnection object at 0x000001ABF6BAD0F0>: Failed to establish a new connection: [WinError 10061] 由于目标计算机积极拒绝，无法连接。')': /wd/hub/session
2020-11-06 19:30:18,397 - connectionpool.py [line:752] - WARNING: Retrying (Retry(total=0, connect=None, read=None, redirect=None, status=None)) after connection broken by 'NewConnectionError('<urllib3.connection.HTTPConnection object at 0x000001ABF6BAD208>: Failed to establish a new connection: [WinError 10061] 由于目标计算机积极拒绝，无法连接。')': /wd/hub/session
2020-11-06 19:30:29,555 - GetDeviceMsgs.py [line:37] - INFO: [{'deviceId': '9c2faa24', 'deviceVersion': '9'}, {'deviceId': 'D8H6R19630008844', 'deviceVersion': '9'}]
2020-11-06 19:44:09,261 - GetDeviceMsgs.py [line:41] - INFO: 成功获取到设备9c2faa24系统版本：9
2020-11-06 19:44:09,371 - GetDeviceMsgs.py [line:41] - INFO: 成功获取到设备D8H6R19630008844系统版本：9
2020-11-06 19:47:03,121 - GetDeviceMsgs.py [line:43] - INFO: 成功获取到设备9c2faa24系统版本：9
2020-11-06 19:48:12,186 - GetDeviceMsgs.py [line:43] - INFO: 成功获取到设备9c2faa24系统版本：9
2020-11-06 19:48:37,330 - GetDeviceMsgs.py [line:43] - INFO: 成功获取到设备9c2faa24系统版本：9
2020-11-06 19:49:02,610 - GetDeviceMsgs.py [line:43] - INFO: 成功获取到设备9c2faa24系统版本：9
2020-11-06 19:49:02,688 - GetDeviceMsgs.py [line:43] - INFO: 成功获取到设备D8H6R19630008844系统版本：9
2020-11-06 19:49:30,454 - GetDeviceMsgs.py [line:43] - INFO: 成功获取到设备9c2faa24系统版本：9
2020-11-06 19:49:30,532 - GetDeviceMsgs.py [line:43] - INFO: 成功获取到设备D8H6R19630008844系统版本：9
2020-11-06 19:50:47,451 - GetDeviceMsgs.py [line:44] - INFO: 成功获取到设备9c2faa24系统版本：9
2020-11-06 19:50:47,514 - GetDeviceMsgs.py [line:44] - INFO: 成功获取到设备D8H6R19630008844系统版本：9
2020-11-06 19:51:40,751 - GetDeviceMsgs.py [line:44] - INFO: 成功获取到设备9c2faa24系统版本：9
2020-11-06 19:51:40,813 - GetDeviceMsgs.py [line:44] - INFO: 成功获取到设备D8H6R19630008844系统版本：9
2020-11-06 19:51:46,333 - remote_connection.py [line:117] - INFO: Could not connect to port 4723 on host 127.0.0.1
2020-11-06 19:51:46,333 - remote_connection.py [line:136] - INFO: Could not get IP address for host: 127.0.0.1
2020-11-06 19:51:48,364 - connectionpool.py [line:752] - WARNING: Retrying (Retry(total=2, connect=None, read=None, redirect=None, status=None)) after connection broken by 'NewConnectionError('<urllib3.connection.HTTPConnection object at 0x000002875A867B38>: Failed to establish a new connection: [WinError 10061] 由于目标计算机积极拒绝，无法连接。')': /wd/hub/session
2020-11-06 19:51:50,402 - connectionpool.py [line:752] - WARNING: Retrying (Retry(total=1, connect=None, read=None, redirect=None, status=None)) after connection broken by 'NewConnectionError('<urllib3.connection.HTTPConnection object at 0x000002875A8A0048>: Failed to establish a new connection: [WinError 10061] 由于目标计算机积极拒绝，无法连接。')': /wd/hub/session
2020-11-06 19:51:52,113 - GetDeviceMsgs.py [line:44] - INFO: 成功获取到设备9c2faa24系统版本：9
2020-11-06 19:51:52,176 - GetDeviceMsgs.py [line:44] - INFO: 成功获取到设备D8H6R19630008844系统版本：9
2020-11-06 19:51:52,431 - connectionpool.py [line:752] - WARNING: Retrying (Retry(total=0, connect=None, read=None, redirect=None, status=None)) after connection broken by 'NewConnectionError('<urllib3.connection.HTTPConnection object at 0x000002875A8A0198>: Failed to establish a new connection: [WinError 10061] 由于目标计算机积极拒绝，无法连接。')': /wd/hub/session
2020-11-06 19:52:18,476 - GetDeviceMsgs.py [line:44] - INFO: 成功获取到设备9c2faa24系统版本：9
2020-11-06 19:52:18,570 - GetDeviceMsgs.py [line:44] - INFO: 成功获取到设备D8H6R19630008844系统版本：9
2020-11-06 19:52:31,916 - GetDeviceMsgs.py [line:44] - INFO: 成功获取到设备9c2faa24系统版本：9
2020-11-06 19:52:32,010 - GetDeviceMsgs.py [line:44] - INFO: 成功获取到设备D8H6R19630008844系统版本：9
2020-11-06 19:52:32,135 - GetDeviceMsgs.py [line:44] - INFO: 成功获取到设备9c2faa24系统版本：9
2020-11-06 19:52:32,198 - GetDeviceMsgs.py [line:44] - INFO: 成功获取到设备D8H6R19630008844系统版本：9
2020-11-06 19:52:45,032 - GetDeviceMsgs.py [line:44] - INFO: 成功获取到设备9c2faa24系统版本：9
2020-11-06 19:52:45,126 - GetDeviceMsgs.py [line:44] - INFO: 成功获取到设备D8H6R19630008844系统版本：9
2020-11-06 20:00:48,440 - remote_connection.py [line:117] - INFO: Could not connect to port 4725 on host 127.0.0.5
2020-11-06 20:00:48,440 - remote_connection.py [line:136] - INFO: Could not get IP address for host: 127.0.0.5
2020-11-06 20:00:50,483 - connectionpool.py [line:752] - WARNING: Retrying (Retry(total=2, connect=None, read=None, redirect=None, status=None)) after connection broken by 'NewConnectionError('<urllib3.connection.HTTPConnection object at 0x000001A0F65C8780>: Failed to establish a new connection: [WinError 10061] 由于目标计算机积极拒绝，无法连接。')': /wd/hub/session
2020-11-06 20:00:52,523 - connectionpool.py [line:752] - WARNING: Retrying (Retry(total=1, connect=None, read=None, redirect=None, status=None)) after connection broken by 'NewConnectionError('<urllib3.connection.HTTPConnection object at 0x000001A0F65C8860>: Failed to establish a new connection: [WinError 10061] 由于目标计算机积极拒绝，无法连接。')': /wd/hub/session
2020-11-06 20:00:54,561 - connectionpool.py [line:752] - WARNING: Retrying (Retry(total=0, connect=None, read=None, redirect=None, status=None)) after connection broken by 'NewConnectionError('<urllib3.connection.HTTPConnection object at 0x000001A0F65C89E8>: Failed to establish a new connection: [WinError 10061] 由于目标计算机积极拒绝，无法连接。')': /wd/hub/session
2020-11-06 20:01:39,573 - remote_connection.py [line:117] - INFO: Could not connect to port 4721 on host 127.0.0.1
2020-11-06 20:01:39,573 - remote_connection.py [line:136] - INFO: Could not get IP address for host: 127.0.0.1
2020-11-06 20:01:41,614 - connectionpool.py [line:752] - WARNING: Retrying (Retry(total=2, connect=None, read=None, redirect=None, status=None)) after connection broken by 'NewConnectionError('<urllib3.connection.HTTPConnection object at 0x000001ECAB8E7860>: Failed to establish a new connection: [WinError 10061] 由于目标计算机积极拒绝，无法连接。')': /wd/hub/session
2020-11-06 20:01:43,677 - connectionpool.py [line:752] - WARNING: Retrying (Retry(total=1, connect=None, read=None, redirect=None, status=None)) after connection broken by 'NewConnectionError('<urllib3.connection.HTTPConnection object at 0x000001ECAB8E7940>: Failed to establish a new connection: [WinError 10061] 由于目标计算机积极拒绝，无法连接。')': /wd/hub/session
2020-11-06 20:01:45,727 - connectionpool.py [line:752] - WARNING: Retrying (Retry(total=0, connect=None, read=None, redirect=None, status=None)) after connection broken by 'NewConnectionError('<urllib3.connection.HTTPConnection object at 0x000001ECAB8E7AC8>: Failed to establish a new connection: [WinError 10061] 由于目标计算机积极拒绝，无法连接。')': /wd/hub/session
2020-11-06 20:01:55,243 - remote_connection.py [line:117] - INFO: Could not connect to port 4721 on host 127.0.0.1
2020-11-06 20:01:55,243 - remote_connection.py [line:136] - INFO: Could not get IP address for host: 127.0.0.1
2020-11-06 20:01:57,267 - connectionpool.py [line:752] - WARNING: Retrying (Retry(total=2, connect=None, read=None, redirect=None, status=None)) after connection broken by 'NewConnectionError('<urllib3.connection.HTTPConnection object at 0x000001DA31637860>: Failed to establish a new connection: [WinError 10061] 由于目标计算机积极拒绝，无法连接。')': /wd/hub/session
2020-11-06 20:01:59,300 - connectionpool.py [line:752] - WARNING: Retrying (Retry(total=1, connect=None, read=None, redirect=None, status=None)) after connection broken by 'NewConnectionError('<urllib3.connection.HTTPConnection object at 0x000001DA31637940>: Failed to establish a new connection: [WinError 10061] 由于目标计算机积极拒绝，无法连接。')': /wd/hub/session
2020-11-06 20:02:01,338 - connectionpool.py [line:752] - WARNING: Retrying (Retry(total=0, connect=None, read=None, redirect=None, status=None)) after connection broken by 'NewConnectionError('<urllib3.connection.HTTPConnection object at 0x000001DA31637AC8>: Failed to establish a new connection: [WinError 10061] 由于目标计算机积极拒绝，无法连接。')': /wd/hub/session
2020-11-06 20:03:44,519 - AppiumServer.py [line:36] - INFO: 初始化成功
2020-11-06 20:03:50,877 - AppiumServer.py [line:36] - INFO: 初始化配置成功
2020-11-06 20:03:56,439 - AppiumServer.py [line:36] - INFO: 读取配置成功
2020-11-06 20:04:19,873 - AppiumServer.py [line:36] - INFO: 读取配置成功,Androidcom.tencent.nowcom.tencent.now.app.startup.LauncherActivity
2020-11-06 20:04:43,787 - AppiumServer.py [line:36] - INFO: 读取配置成功,测试设备Android、com.tencent.nowcom.tencent.now.app.startup.LauncherActivity
2020-11-06 20:04:53,638 - AppiumServer.py [line:36] - INFO: 读取配置成功,测试设备Android 包名：com.tencent.nowcom.tencent.now.app.startup.LauncherActivity
2020-11-06 20:05:07,170 - AppiumServer.py [line:36] - INFO: 读取配置成功,测试设备Android 包名：com.tencent.now 主类名：com.tencent.now.app.startup.LauncherActivity
2020-11-06 20:05:43,083 - AppiumServer.py [line:37] - INFO: 读取配置成功,测试设备0Android 包名：com.tencent.now 主类名：com.tencent.now.app.startup.LauncherActivity
2020-11-06 20:05:43,083 - AppiumServer.py [line:37] - INFO: 读取配置成功,测试设备1Android 包名：com.tencent.now 主类名：com.tencent.now.app.startup.LauncherActivity
2020-11-06 20:06:11,339 - AppiumServer.py [line:37] - INFO: 读取配置成功,测试设备9c2faa24Android 包名：com.tencent.now 主类名：com.tencent.now.app.startup.LauncherActivity
2020-11-06 20:06:11,339 - AppiumServer.py [line:37] - INFO: 读取配置成功,测试设备D8H6R19630008844Android 包名：com.tencent.now 主类名：com.tencent.now.app.startup.LauncherActivity
2020-11-06 20:06:43,320 - AppiumServer.py [line:37] - INFO: 读取配置成功,测试平台Android,设备ID9c2faa24 包名：com.tencent.now 主类名：com.tencent.now.app.startup.LauncherActivity
2020-11-06 20:06:43,320 - AppiumServer.py [line:37] - INFO: 读取配置成功,测试平台Android,设备IDD8H6R19630008844 包名：com.tencent.now 主类名：com.tencent.now.app.startup.LauncherActivity
2020-11-06 20:07:30,905 - AppiumServer.py [line:37] - INFO: 即将初始化配置,测试平台Android,设备ID9c2faa24 包名：com.tencent.now 主类名：com.tencent.now.app.startup.LauncherActivity
2020-11-06 20:07:30,905 - AppiumServer.py [line:37] - INFO: 即将初始化配置,测试平台Android,设备IDD8H6R19630008844 包名：com.tencent.now 主类名：com.tencent.now.app.startup.LauncherActivity
2020-11-06 20:07:39,356 - AppiumServer.py [line:37] - WARNING: 初始化配置ing,测试平台Android,设备ID9c2faa24 包名：com.tencent.now 主类名：com.tencent.now.app.startup.LauncherActivity
2020-11-06 20:07:39,356 - AppiumServer.py [line:37] - WARNING: 初始化配置ing,测试平台Android,设备IDD8H6R19630008844 包名：com.tencent.now 主类名：com.tencent.now.app.startup.LauncherActivity
2020-11-06 20:08:23,340 - AppiumServer.py [line:37] - INFO: 初始化配置ing,测试平台Android,设备ID9c2faa24 包名：com.tencent.now 主类名：com.tencent.now.app.startup.LauncherActivity
2020-11-06 20:08:23,340 - AppiumServer.py [line:37] - INFO: 初始化配置ing,测试平台Android,设备IDD8H6R19630008844 包名：com.tencent.now 主类名：com.tencent.now.app.startup.LauncherActivity
2020-11-06 20:08:47,873 - AppiumServer.py [line:43] - INFO: 初始化配置ing,测试平台Android,设备ID9c2faa24 包名：com.tencent.now 主类名：com.tencent.now.app.startup.LauncherActivity
2020-11-06 20:08:47,873 - AppiumServer.py [line:43] - INFO: 初始化配置ing,测试平台Android,设备IDD8H6R19630008844 包名：com.tencent.now 主类名：com.tencent.now.app.startup.LauncherActivity
2020-11-06 20:08:58,358 - AppiumServer.py [line:43] - INFO: {'platformName': 'Android', 'deviceName': '9c2faa24', 'appPackage': 'com.tencent.now', 'appActivity': 'com.tencent.now.app.startup.LauncherActivity'}
2020-11-06 20:08:58,358 - AppiumServer.py [line:43] - INFO: {'platformName': 'Android', 'deviceName': 'D8H6R19630008844', 'appPackage': 'com.tencent.now', 'appActivity': 'com.tencent.now.app.startup.LauncherActivity'}
2020-11-06 20:10:11,401 - AppiumServer.py [line:43] - INFO: {'platformName': 'Android', 'deviceName': '9c2faa24', 'appPackage': 'com.tencent.now', 'appActivity': 'com.tencent.now.app.startup.LauncherActivity'}
2020-11-06 20:10:11,401 - AppiumServer.py [line:43] - INFO: {'platformName': 'Android', 'deviceName': 'D8H6R19630008844', 'appPackage': 'com.tencent.now', 'appActivity': 'com.tencent.now.app.startup.LauncherActivity'}
2020-11-06 20:12:18,638 - AppiumServer.py [line:44] - INFO: {'platformName': 'Android', 'deviceName': '9c2faa24', 'appPackage': 'com.tencent.now', 'appActivity': 'com.tencent.now.app.startup.LauncherActivity'}
2020-11-06 20:12:18,638 - AppiumServer.py [line:44] - INFO: {'platformName': 'Android', 'deviceName': 'D8H6R19630008844', 'appPackage': 'com.tencent.now', 'appActivity': 'com.tencent.now.app.startup.LauncherActivity'}
2020-11-06 20:12:58,556 - AppiumServer.py [line:44] - INFO: {'platformName': 'Android', 'deviceName': '9c2faa24', 'appPackage': 'com.tencent.now', 'appActivity': 'com.tencent.now.app.startup.LauncherActivity'}
2020-11-06 20:12:58,556 - AppiumServer.py [line:44] - INFO: {'platformName': 'Android', 'deviceName': 'D8H6R19630008844', 'appPackage': 'com.tencent.now', 'appActivity': 'com.tencent.now.app.startup.LauncherActivity'}
2020-11-06 20:13:24,782 - AppiumServer.py [line:44] - INFO: {'platformName': 'Android', 'deviceName': '9c2faa24', 'appPackage': 'com.tencent.now', 'appActivity': 'com.tencent.now.app.startup.LauncherActivity'}
2020-11-06 20:13:24,782 - AppiumServer.py [line:44] - INFO: {'platformName': 'Android', 'deviceName': 'D8H6R19630008844', 'appPackage': 'com.tencent.now', 'appActivity': 'com.tencent.now.app.startup.LauncherActivity'}
2020-11-06 20:13:40,134 - AppiumServer.py [line:44] - INFO: {'platformName': 'Android', 'deviceName': '9c2faa24', 'appPackage': 'com.tencent.now', 'appActivity': 'com.tencent.now.app.startup.LauncherActivity'}
2020-11-06 20:13:40,134 - AppiumServer.py [line:44] - INFO: {'platformName': 'Android', 'deviceName': 'D8H6R19630008844', 'appPackage': 'com.tencent.now', 'appActivity': 'com.tencent.now.app.startup.LauncherActivity'}
2020-11-06 20:13:52,066 - AppiumServer.py [line:44] - INFO: {'platformName': 'Android', 'deviceName': '9c2faa24', 'appPackage': 'com.tencent.now', 'appActivity': 'com.tencent.now.app.startup.LauncherActivity'}
2020-11-06 20:13:52,066 - AppiumServer.py [line:44] - INFO: {'platformName': 'Android', 'deviceName': 'D8H6R19630008844', 'appPackage': 'com.tencent.now', 'appActivity': 'com.tencent.now.app.startup.LauncherActivity'}
2020-11-06 20:14:15,245 - AppiumServer.py [line:44] - INFO: {'platformName': 'Android', 'deviceName': '9c2faa24', 'appPackage': 'com.tencent.now', 'appActivity': 'com.tencent.now.app.startup.LauncherActivity'}
2020-11-06 20:14:15,245 - AppiumServer.py [line:44] - INFO: {'platformName': 'Android', 'deviceName': 'D8H6R19630008844', 'appPackage': 'com.tencent.now', 'appActivity': 'com.tencent.now.app.startup.LauncherActivity'}
2020-11-06 20:15:59,859 - AppiumServer.py [line:44] - INFO: {'platformName': 'Android', 'deviceName': '9c2faa24', 'appPackage': 'com.tencent.now', 'appActivity': 'com.tencent.now.app.startup.LauncherActivity'}
2020-11-06 20:15:59,859 - AppiumServer.py [line:44] - INFO: {'platformName': 'Android', 'deviceName': 'D8H6R19630008844', 'appPackage': 'com.tencent.now', 'appActivity': 'com.tencent.now.app.startup.LauncherActivity'}
2020-11-06 20:16:06,534 - AppiumServer.py [line:44] - INFO: {'platformName': 'Android', 'deviceName': '9c2faa24', 'appPackage': 'com.tencent.now', 'appActivity': 'com.tencent.now.app.startup.LauncherActivity'}
2020-11-06 20:16:06,534 - AppiumServer.py [line:44] - INFO: {'platformName': 'Android', 'deviceName': 'D8H6R19630008844', 'appPackage': 'com.tencent.now', 'appActivity': 'com.tencent.now.app.startup.LauncherActivity'}
2020-11-06 20:16:16,006 - AppiumServer.py [line:44] - INFO: {'platformName': 'Android', 'deviceName': '9c2faa24', 'appPackage': 'com.tencent.now', 'appActivity': 'com.tencent.now.app.startup.LauncherActivity'}
2020-11-06 20:16:16,006 - AppiumServer.py [line:44] - INFO: {'platformName': 'Android', 'deviceName': 'D8H6R19630008844', 'appPackage': 'com.tencent.now', 'appActivity': 'com.tencent.now.app.startup.LauncherActivity'}
2020-11-06 20:19:21,233 - AppiumServer.py [line:44] - INFO: {'platformName': 'Android', 'deviceName': '9c2faa24', 'appPackage': 'com.tencent.now', 'appActivity': 'com.tencent.now.app.startup.LauncherActivity'}
2020-11-06 20:19:21,233 - AppiumServer.py [line:44] - INFO: {'platformName': 'Android', 'deviceName': 'D8H6R19630008844', 'appPackage': 'com.tencent.now', 'appActivity': 'com.tencent.now.app.startup.LauncherActivity'}
2020-11-06 20:19:29,870 - AppiumServer.py [line:44] - INFO: {'platformName': 'Android', 'deviceName': '9c2faa24', 'appPackage': 'com.tencent.now', 'appActivity': 'com.tencent.now.app.startup.LauncherActivity'}
2020-11-06 20:19:29,870 - AppiumServer.py [line:44] - INFO: {'platformName': 'Android', 'deviceName': 'D8H6R19630008844', 'appPackage': 'com.tencent.now', 'appActivity': 'com.tencent.now.app.startup.LauncherActivity'}
2020-11-06 20:19:31,906 - AppiumServer.py [line:58] - INFO: Port 4723 Is Available !,具体返回：[WinError 10061] 由于目标计算机积极拒绝，无法连接。
2020-11-06 20:21:00,585 - AppiumServer.py [line:44] - INFO: {'platformName': 'Android', 'deviceName': '9c2faa24', 'appPackage': 'com.tencent.now', 'appActivity': 'com.tencent.now.app.startup.LauncherActivity'}
2020-11-06 20:21:00,585 - AppiumServer.py [line:44] - INFO: {'platformName': 'Android', 'deviceName': 'D8H6R19630008844', 'appPackage': 'com.tencent.now', 'appActivity': 'com.tencent.now.app.startup.LauncherActivity'}
2020-11-06 20:21:02,615 - AppiumServer.py [line:58] - INFO: 端口：4723 可以用[WinError 10061] 由于目标计算机积极拒绝，无法连接。
2020-11-06 20:22:12,880 - AppiumServer.py [line:44] - INFO: {'platformName': 'Android', 'deviceName': '9c2faa24', 'appPackage': 'com.tencent.now', 'appActivity': 'com.tencent.now.app.startup.LauncherActivity'}
2020-11-06 20:22:12,880 - AppiumServer.py [line:44] - INFO: {'platformName': 'Android', 'deviceName': 'D8H6R19630008844', 'appPackage': 'com.tencent.now', 'appActivity': 'com.tencent.now.app.startup.LauncherActivity'}
2020-11-06 20:22:14,925 - AppiumServer.py [line:58] - INFO: 端口：4723 未启用
2020-11-06 20:22:14,925 - AppiumServer.py [line:59] - INFO: [WinError 10061] 由于目标计算机积极拒绝，无法连接。
2020-11-06 20:23:07,066 - AppiumServer.py [line:44] - INFO: {'platformName': 'Android', 'deviceName': '9c2faa24', 'appPackage': 'com.tencent.now', 'appActivity': 'com.tencent.now.app.startup.LauncherActivity'}
2020-11-06 20:23:07,066 - AppiumServer.py [line:44] - INFO: {'platformName': 'Android', 'deviceName': 'D8H6R19630008844', 'appPackage': 'com.tencent.now', 'appActivity': 'com.tencent.now.app.startup.LauncherActivity'}
2020-11-06 20:23:09,116 - AppiumServer.py [line:58] - INFO: 端口：4723 未启用
2020-11-06 20:23:09,116 - AppiumServer.py [line:59] - INFO: [WinError 10061] 由于目标计算机积极拒绝，无法连接。
2020-11-06 20:23:47,537 - AppiumServer.py [line:44] - INFO: {'platformName': 'Android', 'deviceName': '9c2faa24', 'appPackage': 'com.tencent.now', 'appActivity': 'com.tencent.now.app.startup.LauncherActivity'}
2020-11-06 20:23:47,552 - AppiumServer.py [line:44] - INFO: {'platformName': 'Android', 'deviceName': 'D8H6R19630008844', 'appPackage': 'com.tencent.now', 'appActivity': 'com.tencent.now.app.startup.LauncherActivity'}
2020-11-06 20:23:49,563 - AppiumServer.py [line:58] - INFO: 端口：4723 未启用
2020-11-06 20:23:49,563 - AppiumServer.py [line:59] - INFO: [WinError 10061] 由于目标计算机积极拒绝，无法连接。
2020-11-06 20:23:49,589 - AppiumServer.py [line:85] - ERROR: port 4723 is available !
2020-11-06 20:24:14,580 - AppiumServer.py [line:44] - INFO: {'platformName': 'Android', 'deviceName': '9c2faa24', 'appPackage': 'com.tencent.now', 'appActivity': 'com.tencent.now.app.startup.LauncherActivity'}
2020-11-06 20:24:14,580 - AppiumServer.py [line:44] - INFO: {'platformName': 'Android', 'deviceName': 'D8H6R19630008844', 'appPackage': 'com.tencent.now', 'appActivity': 'com.tencent.now.app.startup.LauncherActivity'}
2020-11-06 20:24:16,618 - AppiumServer.py [line:58] - INFO: 端口：4723 未启用
2020-11-06 20:24:16,618 - AppiumServer.py [line:59] - INFO: [WinError 10061] 由于目标计算机积极拒绝，无法连接。
2020-11-06 20:24:16,644 - AppiumServer.py [line:85] - ERROR: port 555 is available !
2020-11-06 20:24:38,215 - AppiumServer.py [line:44] - INFO: {'platformName': 'Android', 'deviceName': '9c2faa24', 'appPackage': 'com.tencent.now', 'appActivity': 'com.tencent.now.app.startup.LauncherActivity'}
2020-11-06 20:24:38,215 - AppiumServer.py [line:44] - INFO: {'platformName': 'Android', 'deviceName': 'D8H6R19630008844', 'appPackage': 'com.tencent.now', 'appActivity': 'com.tencent.now.app.startup.LauncherActivity'}
2020-11-06 20:24:40,260 - AppiumServer.py [line:58] - INFO: 端口：4723 未启用
2020-11-06 20:24:40,260 - AppiumServer.py [line:59] - INFO: [WinError 10061] 由于目标计算机积极拒绝，无法连接。
2020-11-06 20:24:40,293 - AppiumServer.py [line:85] - ERROR: 端口：555 暂未启用 !
2020-11-06 20:30:40,049 - AppiumTools.py [line:49] - INFO: {'platformName': 'Android', 'deviceName': '9c2faa24', 'appPackage': 'com.tencent.now', 'appActivity': 'com.tencent.now.app.startup.LauncherActivity'}
2020-11-06 20:30:40,049 - AppiumTools.py [line:49] - INFO: {'platformName': 'Android', 'deviceName': 'D8H6R19630008844', 'appPackage': 'com.tencent.now', 'appActivity': 'com.tencent.now.app.startup.LauncherActivity'}
2020-11-06 20:30:42,104 - AppiumTools.py [line:64] - INFO: 端口：4723 未启用
2020-11-06 20:30:42,104 - AppiumTools.py [line:65] - INFO: [WinError 10061] 由于目标计算机积极拒绝，无法连接。
2020-11-06 20:30:42,132 - AppiumTools.py [line:92] - ERROR: 端口：555 暂未启用 !
2020-11-06 20:31:07,890 - AppiumTools.py [line:49] - INFO: {'platformName': 'Android', 'deviceName': '9c2faa24', 'appPackage': 'com.tencent.now', 'appActivity': 'com.tencent.now.app.startup.LauncherActivity'}
2020-11-06 20:31:07,890 - AppiumTools.py [line:49] - INFO: {'platformName': 'Android', 'deviceName': 'D8H6R19630008844', 'appPackage': 'com.tencent.now', 'appActivity': 'com.tencent.now.app.startup.LauncherActivity'}
2020-11-06 20:31:09,938 - AppiumTools.py [line:64] - INFO: 端口：4723 未启用
2020-11-06 20:31:09,938 - AppiumTools.py [line:65] - INFO: [WinError 10061] 由于目标计算机积极拒绝，无法连接。
2020-11-06 20:31:09,969 - AppiumTools.py [line:92] - ERROR: 端口：555 未启用
