2021-01-05 09:21:42,438 - AdbTools.py [line:27] - INFO: 检测到本地为Windows环境
2021-01-05 09:22:14,995 - AdbTools.py [line:27] - INFO: 检测到本地为Windows环境
2021-01-05 09:22:15,979 - LibraryTools.py [line:33] - INFO: 扫描到本地已成功安装所需要库：['os', 're', 'sys', 'xlwt', 'json', 'xlrd', 'time', 'gzip', 'email', 'mysql', 'numpy', 'faker', 'pandas', 'shutil', 'random', 'loguru', 'zipfile', 'logging', 'smtplib', 'datetime', 'platform', 'configobj', 'subprocess', 'configparser', 'requests_toolbelt']
2021-01-05 09:23:10,506 - AdbTools.py [line:27] - INFO: 检测到本地为Windows环境
2021-01-05 09:23:11,109 - LibraryTools.py [line:33] - INFO: 扫描到本地已成功安装所需要库：['os', 're', 'sys', 'xlwt', 'json', 'xlrd', 'time', 'gzip', 'email', 'mysql', 'numpy', 'faker', 'pandas', 'shutil', 'random', 'loguru', 'zipfile', 'logging', 'smtplib', 'datetime', 'platform', 'configobj', 'subprocess', 'configparser', 'requests_toolbelt']
2021-01-05 10:01:16,291 - LibraryTools.py [line:58] - INFO: 检查更新情况:
2021-01-05 11:59:58,112 - remote_connection.py [line:117] - INFO: Could not connect to port 5920 on host 127.0.0.1
2021-01-05 11:59:58,112 - remote_connection.py [line:136] - INFO: Could not get IP address for host: 127.0.0.1
2021-01-05 12:00:00,148 - connectionpool.py [line:752] - WARNING: Retrying (Retry(total=2, connect=None, read=None, redirect=None, status=None)) after connection broken by 'NewConnectionError('<urllib3.connection.HTTPConnection object at 0x000001BC4571EF98>: Failed to establish a new connection: [WinError 10061] 由于目标计算机积极拒绝，无法连接。')': /wd/hub/session
2021-01-05 12:00:02,193 - connectionpool.py [line:752] - WARNING: Retrying (Retry(total=1, connect=None, read=None, redirect=None, status=None)) after connection broken by 'NewConnectionError('<urllib3.connection.HTTPConnection object at 0x000001BC4574C0B8>: Failed to establish a new connection: [WinError 10061] 由于目标计算机积极拒绝，无法连接。')': /wd/hub/session
2021-01-05 12:00:04,206 - connectionpool.py [line:752] - WARNING: Retrying (Retry(total=0, connect=None, read=None, redirect=None, status=None)) after connection broken by 'NewConnectionError('<urllib3.connection.HTTPConnection object at 0x000001BC4574C1D0>: Failed to establish a new connection: [WinError 10061] 由于目标计算机积极拒绝，无法连接。')': /wd/hub/session
2021-01-05 12:00:14,968 - AppiumTools.py [line:48] - INFO: 正在启动Appium服务{IP：127.0.0.1,Port：5920}
